{"time": "2025-02-06 00:52:35,328", "level": "ERROR", "module": "logging_setup", "funcName": "log", "message": "[realtime_price_processor(BTCUSDT)] => name 'final_act' is not defined\nTraceback (most recent call last):\n  File \"/Users/user/Documents/Binance-Trading-Bot-main/advanced_bot2/main.py\", line 181, in realtime_price_processor\n    await strategy_mgr.on_price_update(symbol, price)\n  File \"/Users/user/Documents/Binance-Trading-Bot-main/advanced_bot2/strategy/manager.py\", line 32, in on_price_update\n    await self.tv_strategy.on_price_update(self.ctx, symbol, price)\n  File \"/Users/user/Documents/Binance-Trading-Bot-main/advanced_bot2/strategy/tv_strategy.py\", line 307, in on_price_update\n    if (not st.panic_mode) and (final_act ==  \"BUY\"):\nNameError: name 'final_act' is not defined. Did you mean: 'final_action'?\n"}
{"time": "2025-02-06 00:52:37,754", "level": "INFO", "module": "logging_setup", "funcName": "log", "message": "[BTCUSDT] => final_act=6.0,holygrail_=,total_score=6.0,  panic=False, reentry=False, netPnL=0.00, RL={'stop_atr_mult': 1.0, 'partial_levels': [0.03, 0.06, 0.1], 'partial_ratio': 0.2}"}
{"time": "2025-02-06 00:52:37,778", "level": "ERROR", "module": "logging_setup", "funcName": "log", "message": "[realtime_price_processor(BTCUSDT)] => name 'final_act' is not defined\nTraceback (most recent call last):\n  File \"/Users/user/Documents/Binance-Trading-Bot-main/advanced_bot2/main.py\", line 181, in realtime_price_processor\n    await strategy_mgr.on_price_update(symbol, price)\n  File \"/Users/user/Documents/Binance-Trading-Bot-main/advanced_bot2/strategy/manager.py\", line 32, in on_price_update\n    await self.tv_strategy.on_price_update(self.ctx, symbol, price)\n  File \"/Users/user/Documents/Binance-Trading-Bot-main/advanced_bot2/strategy/tv_strategy.py\", line 307, in on_price_update\n    if (not st.panic_mode) and (final_act ==  \"BUY\"):\nNameError: name 'final_act' is not defined. Did you mean: 'final_action'?\n"}
{"time": "2025-02-06 00:52:40,396", "level": "INFO", "module": "logging_setup", "funcName": "log", "message": "[BTCUSDT] => final_act=6.0,holygrail_=,total_score=6.0,  panic=False, reentry=False, netPnL=0.00, RL={'stop_atr_mult': 1.0, 'partial_levels': [0.03, 0.06, 0.1], 'partial_ratio': 0.2}"}
{"time": "2025-02-06 00:52:40,427", "level": "ERROR", "module": "logging_setup", "funcName": "log", "message": "[realtime_price_processor(BTCUSDT)] => name 'final_act' is not defined\nTraceback (most recent call last):\n  File \"/Users/user/Documents/Binance-Trading-Bot-main/advanced_bot2/main.py\", line 181, in realtime_price_processor\n    await strategy_mgr.on_price_update(symbol, price)\n  File \"/Users/user/Documents/Binance-Trading-Bot-main/advanced_bot2/strategy/manager.py\", line 32, in on_price_update\n    await self.tv_strategy.on_price_update(self.ctx, symbol, price)\n  File \"/Users/user/Documents/Binance-Trading-Bot-main/advanced_bot2/strategy/tv_strategy.py\", line 307, in on_price_update\n    if (not st.panic_mode) and (final_act ==  \"BUY\"):\nNameError: name 'final_act' is not defined. Did you mean: 'final_action'?\n"}
{"time": "2025-02-06 01:53:15,532", "level": "ERROR", "module": "logging_setup", "funcName": "log", "message": "[get_balance] => unknown => HTTPSConnectionPool(host='api.binance.com', port=443): Read timed out. (read timeout=10)\nTraceback (most recent call last):\n  File \"/Users/user/Documents/Binance-Trading-Bot-main/.venv/lib/python3.10/site-packages/urllib3/connectionpool.py\", line 534, in _make_request\n    response = conn.getresponse()\n  File \"/Users/user/Documents/Binance-Trading-Bot-main/.venv/lib/python3.10/site-packages/urllib3/connection.py\", line 516, in getresponse\n    httplib_response = super().getresponse()\n  File \"/usr/local/Cellar/python@3.10/3.10.16/Frameworks/Python.framework/Versions/3.10/lib/python3.10/http/client.py\", line 1375, in getresponse\n    response.begin()\n  File \"/usr/local/Cellar/python@3.10/3.10.16/Frameworks/Python.framework/Versions/3.10/lib/python3.10/http/client.py\", line 318, in begin\n    version, status, reason = self._read_status()\n  File \"/usr/local/Cellar/python@3.10/3.10.16/Frameworks/Python.framework/Versions/3.10/lib/python3.10/http/client.py\", line 279, in _read_status\n    line = str(self.fp.readline(_MAXLINE + 1), \"iso-8859-1\")\n  File \"/usr/local/Cellar/python@3.10/3.10.16/Frameworks/Python.framework/Versions/3.10/lib/python3.10/socket.py\", line 717, in readinto\n    return self._sock.recv_into(b)\n  File \"/usr/local/Cellar/python@3.10/3.10.16/Frameworks/Python.framework/Versions/3.10/lib/python3.10/ssl.py\", line 1307, in recv_into\n    return self.read(nbytes, buffer)\n  File \"/usr/local/Cellar/python@3.10/3.10.16/Frameworks/Python.framework/Versions/3.10/lib/python3.10/ssl.py\", line 1163, in read\n    return self._sslobj.read(len, buffer)\nTimeoutError: The read operation timed out\n\nThe above exception was the direct cause of the following exception:\n\nTraceback (most recent call last):\n  File \"/Users/user/Documents/Binance-Trading-Bot-main/.venv/lib/python3.10/site-packages/requests/adapters.py\", line 667, in send\n    resp = conn.urlopen(\n  File \"/Users/user/Documents/Binance-Trading-Bot-main/.venv/lib/python3.10/site-packages/urllib3/connectionpool.py\", line 841, in urlopen\n    retries = retries.increment(\n  File \"/Users/user/Documents/Binance-Trading-Bot-main/.venv/lib/python3.10/site-packages/urllib3/util/retry.py\", line 474, in increment\n    raise reraise(type(error), error, _stacktrace)\n  File \"/Users/user/Documents/Binance-Trading-Bot-main/.venv/lib/python3.10/site-packages/urllib3/util/util.py\", line 39, in reraise\n    raise value\n  File \"/Users/user/Documents/Binance-Trading-Bot-main/.venv/lib/python3.10/site-packages/urllib3/connectionpool.py\", line 787, in urlopen\n    response = self._make_request(\n  File \"/Users/user/Documents/Binance-Trading-Bot-main/.venv/lib/python3.10/site-packages/urllib3/connectionpool.py\", line 536, in _make_request\n    self._raise_timeout(err=e, url=url, timeout_value=read_timeout)\n  File \"/Users/user/Documents/Binance-Trading-Bot-main/.venv/lib/python3.10/site-packages/urllib3/connectionpool.py\", line 367, in _raise_timeout\n    raise ReadTimeoutError(\nurllib3.exceptions.ReadTimeoutError: HTTPSConnectionPool(host='api.binance.com', port=443): Read timed out. (read timeout=10)\n\nDuring handling of the above exception, another exception occurred:\n\nTraceback (most recent call last):\n  File \"/Users/user/Documents/Binance-Trading-Bot-main/advanced_bot2/exchange_clients/binance_spot_manager_async.py\", line 148, in get_balance\n    bal_info = await self._call_sync(self.client.get_asset_balance, asset=asset)\n  File \"/Users/user/Documents/Binance-Trading-Bot-main/advanced_bot2/exchange_clients/binance_spot_manager_async.py\", line 57, in _call_sync\n    return await loop.run_in_executor(self._executor, lambda: func(*args, **kwargs))\n  File \"/usr/local/Cellar/python@3.10/3.10.16/Frameworks/Python.framework/Versions/3.10/lib/python3.10/concurrent/futures/thread.py\", line 58, in run\n    result = self.fn(*self.args, **self.kwargs)\n  File \"/Users/user/Documents/Binance-Trading-Bot-main/advanced_bot2/exchange_clients/binance_spot_manager_async.py\", line 57, in <lambda>\n    return await loop.run_in_executor(self._executor, lambda: func(*args, **kwargs))\n  File \"/Users/user/Documents/Binance-Trading-Bot-main/.venv/lib/python3.10/site-packages/binance/client.py\", line 2059, in get_asset_balance\n    res = self.get_account(**params)\n  File \"/Users/user/Documents/Binance-Trading-Bot-main/.venv/lib/python3.10/site-packages/binance/client.py\", line 2036, in get_account\n    return self._get(\"account\", True, data=params)\n  File \"/Users/user/Documents/Binance-Trading-Bot-main/.venv/lib/python3.10/site-packages/binance/client.py\", line 176, in _get\n    return self._request_api(\"get\", path, signed, version, **kwargs)\n  File \"/Users/user/Documents/Binance-Trading-Bot-main/.venv/lib/python3.10/site-packages/binance/client.py\", line 113, in _request_api\n    return self._request(method, uri, signed, **kwargs)\n  File \"/Users/user/Documents/Binance-Trading-Bot-main/.venv/lib/python3.10/site-packages/binance/client.py\", line 88, in _request\n    self.response = getattr(self.session, method)(uri, headers=headers, data=data, **kwargs)\n  File \"/Users/user/Documents/Binance-Trading-Bot-main/.venv/lib/python3.10/site-packages/requests/sessions.py\", line 602, in get\n    return self.request(\"GET\", url, **kwargs)\n  File \"/Users/user/Documents/Binance-Trading-Bot-main/.venv/lib/python3.10/site-packages/requests/sessions.py\", line 589, in request\n    resp = self.send(prep, **send_kwargs)\n  File \"/Users/user/Documents/Binance-Trading-Bot-main/.venv/lib/python3.10/site-packages/requests/sessions.py\", line 703, in send\n    r = adapter.send(request, **kwargs)\n  File \"/Users/user/Documents/Binance-Trading-Bot-main/.venv/lib/python3.10/site-packages/requests/adapters.py\", line 713, in send\n    raise ReadTimeout(e, request=request)\nrequests.exceptions.ReadTimeout: HTTPSConnectionPool(host='api.binance.com', port=443): Read timed out. (read timeout=10)\n"}
{"time": "2025-02-06 01:53:15,610", "level": "WARNING", "module": "logging_setup", "funcName": "log", "message": "[DDCheck] => drawdown=100.00%>15.00% => closeAll"}
{"time": "2025-02-06 01:53:15,756", "level": "ERROR", "module": "logging_setup", "funcName": "log", "message": "[loop_data_collector] => Cannot connect to host api.binance.com:443 ssl:default [Could not contact DNS servers]\nTraceback (most recent call last):\n  File \"/Users/user/Documents/Binance-Trading-Bot-main/.venv/lib/python3.10/site-packages/aiohttp/resolver.py\", line 105, in resolve\n    resp = await self._resolver.getaddrinfo(\naiodns.error.DNSError: (11, 'Could not contact DNS servers')\n\nThe above exception was the direct cause of the following exception:\n\nTraceback (most recent call last):\n  File \"/Users/user/Documents/Binance-Trading-Bot-main/.venv/lib/python3.10/site-packages/aiohttp/connector.py\", line 1335, in _create_direct_connection\n    hosts = await self._resolve_host(host, port, traces=traces)\n  File \"/Users/user/Documents/Binance-Trading-Bot-main/.venv/lib/python3.10/site-packages/aiohttp/connector.py\", line 989, in _resolve_host\n    return await asyncio.shield(resolved_host_task)\n  File \"/Users/user/Documents/Binance-Trading-Bot-main/.venv/lib/python3.10/site-packages/aiohttp/connector.py\", line 1020, in _resolve_host_with_throttle\n    addrs = await self._resolver.resolve(host, port, family=self._family)\n  File \"/Users/user/Documents/Binance-Trading-Bot-main/.venv/lib/python3.10/site-packages/aiohttp/resolver.py\", line 114, in resolve\n    raise OSError(None, msg) from exc\nOSError: [Errno None] Could not contact DNS servers\n\nThe above exception was the direct cause of the following exception:\n\nTraceback (most recent call last):\n  File \"/Users/user/Documents/Binance-Trading-Bot-main/advanced_bot2/data/data_collector.py\", line 617, in loop_data_collector\n    df_1m = await update_klines_csv(ctx.client_async, s, \"1m\", csv_1m_path, max_rows=50000)\n  File \"/Users/user/Documents/Binance-Trading-Bot-main/advanced_bot2/data/data_collector.py\", line 182, in update_klines_csv\n    new_klines = await client.get_historical_klines(symbol, timeframe, fetch_start_str)\n  File \"/Users/user/Documents/Binance-Trading-Bot-main/.venv/lib/python3.10/site-packages/binance/async_client.py\", line 462, in get_historical_klines\n    return await self._historical_klines(\n  File \"/Users/user/Documents/Binance-Trading-Bot-main/.venv/lib/python3.10/site-packages/binance/async_client.py\", line 496, in _historical_klines\n    first_valid_ts = await self._get_earliest_valid_timestamp(\n  File \"/Users/user/Documents/Binance-Trading-Bot-main/.venv/lib/python3.10/site-packages/binance/async_client.py\", line 441, in _get_earliest_valid_timestamp\n    kline = await self._klines(\n  File \"/Users/user/Documents/Binance-Trading-Bot-main/.venv/lib/python3.10/site-packages/binance/async_client.py\", line 417, in _klines\n    return await self.get_klines(**params)\n  File \"/Users/user/Documents/Binance-Trading-Bot-main/.venv/lib/python3.10/site-packages/binance/async_client.py\", line 407, in get_klines\n    return await self._get(\"klines\", data=params, version=self.PRIVATE_API_VERSION)\n  File \"/Users/user/Documents/Binance-Trading-Bot-main/.venv/lib/python3.10/site-packages/binance/async_client.py\", line 245, in _get\n    return await self._request_api(\"get\", path, signed, version, **kwargs)\n  File \"/Users/user/Documents/Binance-Trading-Bot-main/.venv/lib/python3.10/site-packages/binance/async_client.py\", line 180, in _request_api\n    return await self._request(method, uri, signed, force_params, **kwargs)\n  File \"/Users/user/Documents/Binance-Trading-Bot-main/.venv/lib/python3.10/site-packages/binance/async_client.py\", line 147, in _request\n    async with getattr(self.session, method)(\n  File \"/Users/user/Documents/Binance-Trading-Bot-main/.venv/lib/python3.10/site-packages/aiohttp/client.py\", line 1360, in __aenter__\n    self._resp: _RetType = await self._coro\n  File \"/Users/user/Documents/Binance-Trading-Bot-main/.venv/lib/python3.10/site-packages/aiohttp/client.py\", line 663, in _request\n    conn = await self._connector.connect(\n  File \"/Users/user/Documents/Binance-Trading-Bot-main/.venv/lib/python3.10/site-packages/aiohttp/connector.py\", line 538, in connect\n    proto = await self._create_connection(req, traces, timeout)\n  File \"/Users/user/Documents/Binance-Trading-Bot-main/.venv/lib/python3.10/site-packages/aiohttp/connector.py\", line 1050, in _create_connection\n    _, proto = await self._create_direct_connection(req, traces, timeout)\n  File \"/Users/user/Documents/Binance-Trading-Bot-main/.venv/lib/python3.10/site-packages/aiohttp/connector.py\", line 1341, in _create_direct_connection\n    raise ClientConnectorDNSError(req.connection_key, exc) from exc\naiohttp.client_exceptions.ClientConnectorDNSError: Cannot connect to host api.binance.com:443 ssl:default [Could not contact DNS servers]\n"}
{"time": "2025-02-06 01:53:24,481", "level": "INFO", "module": "logging_setup", "funcName": "log", "message": "[BTCUSDT] => final_act=6.0,holygrail_=,total_score=6.0,  panic=False, reentry=False, netPnL=0.00, RL={'stop_atr_mult': 1.0, 'partial_levels': [0.03, 0.06, 0.1], 'partial_ratio': 0.2}"}
{"time": "2025-02-06 02:03:41,543", "level": "INFO", "module": "logging_setup", "funcName": "log", "message": "main() => starting"}
{"time": "2025-02-06 02:03:41,544", "level": "INFO", "module": "logging_setup", "funcName": "log", "message": "start_trading => begin"}
{"time": "2025-02-06 02:03:46,381", "level": "ERROR", "module": "logging_setup", "funcName": "log", "message": "[get_balance] => APIError(code=-2015): Invalid API-key, IP, or permissions for action.\nTraceback (most recent call last):\n  File \"/Users/user/Documents/Binance-Trading-Bot-main/advanced_bot2/exchange_clients/binance_spot_manager_async.py\", line 148, in get_balance\n    bal_info = await self._call_sync(self.client.get_asset_balance, asset=asset)\n  File \"/Users/user/Documents/Binance-Trading-Bot-main/advanced_bot2/exchange_clients/binance_spot_manager_async.py\", line 57, in _call_sync\n    return await loop.run_in_executor(self._executor, lambda: func(*args, **kwargs))\n  File \"/usr/local/Cellar/python@3.10/3.10.16/Frameworks/Python.framework/Versions/3.10/lib/python3.10/concurrent/futures/thread.py\", line 58, in run\n    result = self.fn(*self.args, **self.kwargs)\n  File \"/Users/user/Documents/Binance-Trading-Bot-main/advanced_bot2/exchange_clients/binance_spot_manager_async.py\", line 57, in <lambda>\n    return await loop.run_in_executor(self._executor, lambda: func(*args, **kwargs))\n  File \"/Users/user/Documents/Binance-Trading-Bot-main/.venv/lib/python3.10/site-packages/binance/client.py\", line 2059, in get_asset_balance\n    res = self.get_account(**params)\n  File \"/Users/user/Documents/Binance-Trading-Bot-main/.venv/lib/python3.10/site-packages/binance/client.py\", line 2036, in get_account\n    return self._get(\"account\", True, data=params)\n  File \"/Users/user/Documents/Binance-Trading-Bot-main/.venv/lib/python3.10/site-packages/binance/client.py\", line 176, in _get\n    return self._request_api(\"get\", path, signed, version, **kwargs)\n  File \"/Users/user/Documents/Binance-Trading-Bot-main/.venv/lib/python3.10/site-packages/binance/client.py\", line 113, in _request_api\n    return self._request(method, uri, signed, **kwargs)\n  File \"/Users/user/Documents/Binance-Trading-Bot-main/.venv/lib/python3.10/site-packages/binance/client.py\", line 89, in _request\n    return self._handle_response(self.response)\n  File \"/Users/user/Documents/Binance-Trading-Bot-main/.venv/lib/python3.10/site-packages/binance/client.py\", line 98, in _handle_response\n    raise BinanceAPIException(response, response.status_code, response.text)\nbinance.exceptions.BinanceAPIException: APIError(code=-2015): Invalid API-key, IP, or permissions for action.\n"}
{"time": "2025-02-06 02:03:46,381", "level": "INFO", "module": "logging_setup", "funcName": "log", "message": "start_trading => started tasks"}
{"time": "2025-02-06 02:03:47,327", "level": "ERROR", "module": "logging_setup", "funcName": "log", "message": "[user_data_reader] Kopma => APIError(code=-2015): Invalid API-key, IP, or permissions for action.\n Reconnect 5s"}
{"time": "2025-02-06 02:03:49,700", "level": "ERROR", "module": "logging_setup", "funcName": "log", "message": "[get_balance] => APIError(code=-2015): Invalid API-key, IP, or permissions for action.\nTraceback (most recent call last):\n  File \"/Users/user/Documents/Binance-Trading-Bot-main/advanced_bot2/exchange_clients/binance_spot_manager_async.py\", line 148, in get_balance\n    bal_info = await self._call_sync(self.client.get_asset_balance, asset=asset)\n  File \"/Users/user/Documents/Binance-Trading-Bot-main/advanced_bot2/exchange_clients/binance_spot_manager_async.py\", line 57, in _call_sync\n    return await loop.run_in_executor(self._executor, lambda: func(*args, **kwargs))\n  File \"/usr/local/Cellar/python@3.10/3.10.16/Frameworks/Python.framework/Versions/3.10/lib/python3.10/concurrent/futures/thread.py\", line 58, in run\n    result = self.fn(*self.args, **self.kwargs)\n  File \"/Users/user/Documents/Binance-Trading-Bot-main/advanced_bot2/exchange_clients/binance_spot_manager_async.py\", line 57, in <lambda>\n    return await loop.run_in_executor(self._executor, lambda: func(*args, **kwargs))\n  File \"/Users/user/Documents/Binance-Trading-Bot-main/.venv/lib/python3.10/site-packages/binance/client.py\", line 2059, in get_asset_balance\n    res = self.get_account(**params)\n  File \"/Users/user/Documents/Binance-Trading-Bot-main/.venv/lib/python3.10/site-packages/binance/client.py\", line 2036, in get_account\n    return self._get(\"account\", True, data=params)\n  File \"/Users/user/Documents/Binance-Trading-Bot-main/.venv/lib/python3.10/site-packages/binance/client.py\", line 176, in _get\n    return self._request_api(\"get\", path, signed, version, **kwargs)\n  File \"/Users/user/Documents/Binance-Trading-Bot-main/.venv/lib/python3.10/site-packages/binance/client.py\", line 113, in _request_api\n    return self._request(method, uri, signed, **kwargs)\n  File \"/Users/user/Documents/Binance-Trading-Bot-main/.venv/lib/python3.10/site-packages/binance/client.py\", line 89, in _request\n    return self._handle_response(self.response)\n  File \"/Users/user/Documents/Binance-Trading-Bot-main/.venv/lib/python3.10/site-packages/binance/client.py\", line 98, in _handle_response\n    raise BinanceAPIException(response, response.status_code, response.text)\nbinance.exceptions.BinanceAPIException: APIError(code=-2015): Invalid API-key, IP, or permissions for action.\n"}
{"time": "2025-02-06 02:03:49,701", "level": "ERROR", "module": "logging_setup", "funcName": "log", "message": "[realtime_price_processor(BTCUSDT)] => float division by zero\nTraceback (most recent call last):\n  File \"/Users/user/Documents/Binance-Trading-Bot-main/advanced_bot2/main.py\", line 181, in realtime_price_processor\n    await strategy_mgr.on_price_update(symbol, price)\n  File \"/Users/user/Documents/Binance-Trading-Bot-main/advanced_bot2/strategy/manager.py\", line 32, in on_price_update\n    await self.tv_strategy.on_price_update(self.ctx, symbol, price)\n  File \"/Users/user/Documents/Binance-Trading-Bot-main/advanced_bot2/strategy/tv_strategy.py\", line 136, in on_price_update\n    dd = self.pm.calc_drawdown(self.total_equity)\n  File \"/Users/user/Documents/Binance-Trading-Bot-main/advanced_bot2/portfolio/portfolio_manager.py\", line 39, in calc_drawdown\n    dd = (self.initial_equity - current_eq) / self.initial_equity\nZeroDivisionError: float division by zero\n"}
{"time": "2025-02-06 02:03:51,967", "level": "ERROR", "module": "logging_setup", "funcName": "log", "message": "[get_balance] => APIError(code=-2015): Invalid API-key, IP, or permissions for action.\nTraceback (most recent call last):\n  File \"/Users/user/Documents/Binance-Trading-Bot-main/advanced_bot2/exchange_clients/binance_spot_manager_async.py\", line 148, in get_balance\n    bal_info = await self._call_sync(self.client.get_asset_balance, asset=asset)\n  File \"/Users/user/Documents/Binance-Trading-Bot-main/advanced_bot2/exchange_clients/binance_spot_manager_async.py\", line 57, in _call_sync\n    return await loop.run_in_executor(self._executor, lambda: func(*args, **kwargs))\n  File \"/usr/local/Cellar/python@3.10/3.10.16/Frameworks/Python.framework/Versions/3.10/lib/python3.10/concurrent/futures/thread.py\", line 58, in run\n    result = self.fn(*self.args, **self.kwargs)\n  File \"/Users/user/Documents/Binance-Trading-Bot-main/advanced_bot2/exchange_clients/binance_spot_manager_async.py\", line 57, in <lambda>\n    return await loop.run_in_executor(self._executor, lambda: func(*args, **kwargs))\n  File \"/Users/user/Documents/Binance-Trading-Bot-main/.venv/lib/python3.10/site-packages/binance/client.py\", line 2059, in get_asset_balance\n    res = self.get_account(**params)\n  File \"/Users/user/Documents/Binance-Trading-Bot-main/.venv/lib/python3.10/site-packages/binance/client.py\", line 2036, in get_account\n    return self._get(\"account\", True, data=params)\n  File \"/Users/user/Documents/Binance-Trading-Bot-main/.venv/lib/python3.10/site-packages/binance/client.py\", line 176, in _get\n    return self._request_api(\"get\", path, signed, version, **kwargs)\n  File \"/Users/user/Documents/Binance-Trading-Bot-main/.venv/lib/python3.10/site-packages/binance/client.py\", line 113, in _request_api\n    return self._request(method, uri, signed, **kwargs)\n  File \"/Users/user/Documents/Binance-Trading-Bot-main/.venv/lib/python3.10/site-packages/binance/client.py\", line 89, in _request\n    return self._handle_response(self.response)\n  File \"/Users/user/Documents/Binance-Trading-Bot-main/.venv/lib/python3.10/site-packages/binance/client.py\", line 98, in _handle_response\n    raise BinanceAPIException(response, response.status_code, response.text)\nbinance.exceptions.BinanceAPIException: APIError(code=-2015): Invalid API-key, IP, or permissions for action.\n"}
{"time": "2025-02-06 02:03:51,968", "level": "ERROR", "module": "logging_setup", "funcName": "log", "message": "[realtime_price_processor(BTCUSDT)] => float division by zero\nTraceback (most recent call last):\n  File \"/Users/user/Documents/Binance-Trading-Bot-main/advanced_bot2/main.py\", line 181, in realtime_price_processor\n    await strategy_mgr.on_price_update(symbol, price)\n  File \"/Users/user/Documents/Binance-Trading-Bot-main/advanced_bot2/strategy/manager.py\", line 32, in on_price_update\n    await self.tv_strategy.on_price_update(self.ctx, symbol, price)\n  File \"/Users/user/Documents/Binance-Trading-Bot-main/advanced_bot2/strategy/tv_strategy.py\", line 136, in on_price_update\n    dd = self.pm.calc_drawdown(self.total_equity)\n  File \"/Users/user/Documents/Binance-Trading-Bot-main/advanced_bot2/portfolio/portfolio_manager.py\", line 39, in calc_drawdown\n    dd = (self.initial_equity - current_eq) / self.initial_equity\nZeroDivisionError: float division by zero\n"}
{"time": "2025-02-06 02:03:52,604", "level": "ERROR", "module": "logging_setup", "funcName": "log", "message": "[user_data_reader] Kopma => APIError(code=-2015): Invalid API-key, IP, or permissions for action.\n Reconnect 5s"}
